<robot name="drawer">
    <link name="world"/>

    <joint name="fixed" type="fixed">
        <parent link="world"/>
        <child link="base_link"/>
        <origin xyz="0 0 0"/>
    </joint>

    <link name="base_link">
        <inertial>
            <origin rpy="0 0 0" xyz="0 0 0"/>
            <mass value="1.0"/>
            <inertia ixx="1.0" ixy="0" ixz="0" iyy="1.0" iyz="0" izz="1.0"/>
        </inertial>
        <visual>
            <origin rpy="0 0 0" xyz="0 0 0"/>
            <geometry>
                <mesh filename="drawer/base_link.obj" scale="1 1 1" />
            </geometry>
        </visual>
        <collision>
            <origin rpy="0 0 0" xyz="0 0 0"/>
            <geometry>
                <mesh filename="drawer/base_link_vhacd.obj" scale="1 1 1" />
            </geometry>
        </collision>
    </link>

    <link name="drawer1">
        <inertial>
            <origin rpy="0 0 0" xyz="0 0 0"/>
            <mass value="2.0"/>
            <inertia ixx="0.01333" ixy="0" ixz="0" iyy="0.01333" iyz="0" izz="0.01333"/>
        </inertial>
        <visual>
            <origin rpy="0 0 0" xyz="0 0 0"/>
            <geometry>
                <mesh filename="drawer/drawer.obj" scale="1 1 1" />
            </geometry>
        </visual>
        <collision>
            <origin rpy="0 0 0" xyz="0 0 0"/>
            <geometry>
                <mesh filename="drawer/drawer_vhacd.obj" scale="1 1 1" />
            </geometry>
        </collision>
    </link>

    <joint name="joint_base_drawer1" type="prismatic">
        <parent link="base_link"/>
        <child link="drawer1"/>
        <dynamics damping="1.0" friction="0.0001"/>
        <limit lower="-0.25" upper="0"/>
        <origin xyz="0 -0.16 0.1"/>
        <axis xyz="0 1 0"/>
    </joint>

    <link name="drawer2">
        <inertial>
            <origin rpy="0 0 0" xyz="0 0 0"/>
            <mass value="2.0"/>
            <inertia ixx="0.01333" ixy="0" ixz="0" iyy="0.01333" iyz="0" izz="0.01333"/>
        </inertial>
        <visual>
            <origin rpy="0 0 0" xyz="0 0 0"/>
            <geometry>
                <mesh filename="drawer/drawer.obj" scale="1 1 1" />
            </geometry>
        </visual>
        <collision>
            <origin rpy="0 0 0" xyz="0 0 0"/>
            <geometry>
                <mesh filename="drawer/drawer_vhacd.obj" scale="1 1 1" />
            </geometry>
        </collision>
    </link>

    <joint name="joint_base_drawer2" type="prismatic">
        <parent link="base_link"/>
        <child link="drawer2"/>
        <dynamics damping="1.0" friction="0.0001"/>
        <limit lower="-0.25" upper="0"/>
        <origin xyz="0 -0.16 0.26"/>
        <axis xyz="0 1 0"/>
    </joint>
</robot>
